[2025-07-28T12:16:53.151+0000] {taskinstance.py:1956} INFO - Dependencies all met for dep_context=non-requeueable deps ti=<TaskInstance: dbt_pipeline.dbt_debug scheduled__2025-07-27T00:00:00+00:00 [queued]>
[2025-07-28T12:16:53.154+0000] {taskinstance.py:1956} INFO - Dependencies all met for dep_context=requeueable deps ti=<TaskInstance: dbt_pipeline.dbt_debug scheduled__2025-07-27T00:00:00+00:00 [queued]>
[2025-07-28T12:16:53.154+0000] {taskinstance.py:2170} INFO - Starting attempt 6 of 7
[2025-07-28T12:16:53.159+0000] {taskinstance.py:2191} INFO - Executing <Task(BashOperator): dbt_debug> on 2025-07-27 00:00:00+00:00
[2025-07-28T12:16:53.162+0000] {standard_task_runner.py:60} INFO - Started process 145 to run task
[2025-07-28T12:16:53.164+0000] {standard_task_runner.py:87} INFO - Running: ['***', 'tasks', 'run', 'dbt_pipeline', 'dbt_debug', 'scheduled__2025-07-27T00:00:00+00:00', '--job-id', '11', '--raw', '--subdir', 'DAGS_FOLDER/dbt_pipeline.py', '--cfg-path', '/tmp/tmppvz2ww_t']
[2025-07-28T12:16:53.165+0000] {standard_task_runner.py:88} INFO - Job 11: Subtask dbt_debug
[2025-07-28T12:16:53.172+0000] {warnings.py:109} WARNING - /home/***/.local/lib/python3.8/site-packages/***/settings.py:194: DeprecationWarning: The sql_alchemy_conn option in [core] has been moved to the sql_alchemy_conn option in [database] - the old setting has been used, but please update your config.
  SQL_ALCHEMY_CONN = conf.get("database", "SQL_ALCHEMY_CONN")

[2025-07-28T12:16:53.193+0000] {task_command.py:423} INFO - Running <TaskInstance: dbt_pipeline.dbt_debug scheduled__2025-07-27T00:00:00+00:00 [running]> on host 283c7a660257
[2025-07-28T12:16:53.222+0000] {taskinstance.py:2480} INFO - Exporting env vars: AIRFLOW_CTX_DAG_OWNER='gotphoto' AIRFLOW_CTX_DAG_ID='dbt_pipeline' AIRFLOW_CTX_TASK_ID='dbt_debug' AIRFLOW_CTX_EXECUTION_DATE='2025-07-27T00:00:00+00:00' AIRFLOW_CTX_TRY_NUMBER='6' AIRFLOW_CTX_DAG_RUN_ID='scheduled__2025-07-27T00:00:00+00:00'
[2025-07-28T12:16:53.225+0000] {subprocess.py:63} INFO - Tmp dir root location: /tmp
[2025-07-28T12:16:53.225+0000] {subprocess.py:75} INFO - Running command: ['/usr/bin/bash', '-c', 'cd /opt/***/dbt_project && dbt debug --project-dir . --profiles-dir profiles']
[2025-07-28T12:16:53.230+0000] {subprocess.py:86} INFO - Output:
[2025-07-28T12:16:54.082+0000] {subprocess.py:93} INFO - [0m12:16:54  Running with dbt=1.8.7
[2025-07-28T12:16:54.089+0000] {subprocess.py:93} INFO - [0m12:16:54  dbt version: 1.8.7
[2025-07-28T12:16:54.089+0000] {subprocess.py:93} INFO - [0m12:16:54  python version: 3.8.18
[2025-07-28T12:16:54.089+0000] {subprocess.py:93} INFO - [0m12:16:54  python path: /usr/local/bin/python
[2025-07-28T12:16:54.089+0000] {subprocess.py:93} INFO - [0m12:16:54  os info: Linux-6.12.5-linuxkit-aarch64-with-glibc2.34
[2025-07-28T12:16:55.102+0000] {subprocess.py:93} INFO - [0m12:16:55  Using profiles dir at profiles
[2025-07-28T12:16:55.102+0000] {subprocess.py:93} INFO - [0m12:16:55  Using profiles.yml file at profiles/profiles.yml
[2025-07-28T12:16:55.103+0000] {subprocess.py:93} INFO - [0m12:16:55  Using dbt_project.yml file at ./dbt_project.yml
[2025-07-28T12:16:55.103+0000] {subprocess.py:93} INFO - [0m12:16:55  adapter type: snowflake
[2025-07-28T12:16:55.103+0000] {subprocess.py:93} INFO - [0m12:16:55  adapter version: 1.8.4
[2025-07-28T12:16:55.147+0000] {subprocess.py:93} INFO - [0m12:16:55  Configuration:
[2025-07-28T12:16:55.147+0000] {subprocess.py:93} INFO - [0m12:16:55    profiles.yml file [[32mOK found and valid[0m]
[2025-07-28T12:16:55.147+0000] {subprocess.py:93} INFO - [0m12:16:55    dbt_project.yml file [[32mOK found and valid[0m]
[2025-07-28T12:16:55.148+0000] {subprocess.py:93} INFO - [0m12:16:55  Required dependencies:
[2025-07-28T12:16:55.155+0000] {subprocess.py:93} INFO - [0m12:16:55   - git [[31mERROR[0m]
[2025-07-28T12:16:55.156+0000] {subprocess.py:93} INFO - 
[2025-07-28T12:16:55.156+0000] {subprocess.py:93} INFO - [0m12:16:55  Connection:
[2025-07-28T12:16:55.156+0000] {subprocess.py:93} INFO - [0m12:16:55    account: ANBZLMX-TB05856
[2025-07-28T12:16:55.156+0000] {subprocess.py:93} INFO - [0m12:16:55    user: gotphoto_etl_user
[2025-07-28T12:16:55.156+0000] {subprocess.py:93} INFO - [0m12:16:55    database: GOTPHOTO_ANALYTICS_DB
[2025-07-28T12:16:55.157+0000] {subprocess.py:93} INFO - [0m12:16:55    warehouse: GOTPHOTO_WH
[2025-07-28T12:16:55.157+0000] {subprocess.py:93} INFO - [0m12:16:55    role: gotphoto_etl_role
[2025-07-28T12:16:55.157+0000] {subprocess.py:93} INFO - [0m12:16:55    schema: STAGING
[2025-07-28T12:16:55.157+0000] {subprocess.py:93} INFO - [0m12:16:55    authenticator: None
[2025-07-28T12:16:55.157+0000] {subprocess.py:93} INFO - [0m12:16:55    oauth_client_id: None
[2025-07-28T12:16:55.158+0000] {subprocess.py:93} INFO - [0m12:16:55    query_tag: None
[2025-07-28T12:16:55.158+0000] {subprocess.py:93} INFO - [0m12:16:55    client_session_keep_alive: True
[2025-07-28T12:16:55.158+0000] {subprocess.py:93} INFO - [0m12:16:55    host: None
[2025-07-28T12:16:55.158+0000] {subprocess.py:93} INFO - [0m12:16:55    port: None
[2025-07-28T12:16:55.159+0000] {subprocess.py:93} INFO - [0m12:16:55    proxy_host: None
[2025-07-28T12:16:55.159+0000] {subprocess.py:93} INFO - [0m12:16:55    proxy_port: None
[2025-07-28T12:16:55.159+0000] {subprocess.py:93} INFO - [0m12:16:55    protocol: None
[2025-07-28T12:16:55.159+0000] {subprocess.py:93} INFO - [0m12:16:55    connect_retries: 1
[2025-07-28T12:16:55.159+0000] {subprocess.py:93} INFO - [0m12:16:55    connect_timeout: None
[2025-07-28T12:16:55.160+0000] {subprocess.py:93} INFO - [0m12:16:55    retry_on_database_errors: False
[2025-07-28T12:16:55.160+0000] {subprocess.py:93} INFO - [0m12:16:55    retry_all: False
[2025-07-28T12:16:55.160+0000] {subprocess.py:93} INFO - [0m12:16:55    insecure_mode: False
[2025-07-28T12:16:55.160+0000] {subprocess.py:93} INFO - [0m12:16:55    reuse_connections: None
[2025-07-28T12:16:55.161+0000] {subprocess.py:93} INFO - [0m12:16:55  Registered adapter: snowflake=1.8.4
[2025-07-28T12:16:56.142+0000] {subprocess.py:93} INFO - [0m12:16:56    Connection test: [[31mERROR[0m]
[2025-07-28T12:16:56.143+0000] {subprocess.py:93} INFO - 
[2025-07-28T12:16:56.143+0000] {subprocess.py:93} INFO - [0m12:16:56  [31m2 checks failed:[0m
[2025-07-28T12:16:56.143+0000] {subprocess.py:93} INFO - [0m12:16:56  Error from git --help: User does not have permissions for this command: "git"
[2025-07-28T12:16:56.143+0000] {subprocess.py:93} INFO - 
[2025-07-28T12:16:56.143+0000] {subprocess.py:93} INFO - [0m12:16:56  dbt was unable to connect to the specified database.
[2025-07-28T12:16:56.143+0000] {subprocess.py:93} INFO - The database returned the following error:
[2025-07-28T12:16:56.143+0000] {subprocess.py:93} INFO - 
[2025-07-28T12:16:56.143+0000] {subprocess.py:93} INFO -   >Database Error
[2025-07-28T12:16:56.143+0000] {subprocess.py:93} INFO -   250001 (08001): Failed to connect to DB: ANBZLMX-TB05856.snowflakecomputing.com:443. Incorrect username or password was specified.
[2025-07-28T12:16:56.143+0000] {subprocess.py:93} INFO - 
[2025-07-28T12:16:56.143+0000] {subprocess.py:93} INFO - Check your database credentials and try again. For more information, visit:
[2025-07-28T12:16:56.144+0000] {subprocess.py:93} INFO - https://docs.getdbt.com/docs/configure-your-profile
[2025-07-28T12:16:56.144+0000] {subprocess.py:93} INFO - 
[2025-07-28T12:16:56.144+0000] {subprocess.py:93} INFO - 
[2025-07-28T12:16:56.886+0000] {subprocess.py:97} INFO - Command exited with return code 1
[2025-07-28T12:16:56.892+0000] {taskinstance.py:2698} ERROR - Task failed with exception
Traceback (most recent call last):
  File "/home/airflow/.local/lib/python3.8/site-packages/airflow/models/taskinstance.py", line 433, in _execute_task
    result = execute_callable(context=context, **execute_callable_kwargs)
  File "/home/airflow/.local/lib/python3.8/site-packages/airflow/operators/bash.py", line 212, in execute
    raise AirflowException(
airflow.exceptions.AirflowException: Bash command failed. The command returned a non-zero exit code 1.
[2025-07-28T12:16:56.894+0000] {taskinstance.py:1138} INFO - Marking task as UP_FOR_RETRY. dag_id=dbt_pipeline, task_id=dbt_debug, execution_date=20250727T000000, start_date=20250728T121653, end_date=20250728T121656
[2025-07-28T12:16:56.900+0000] {standard_task_runner.py:107} ERROR - Failed to execute job 11 for task dbt_debug (Bash command failed. The command returned a non-zero exit code 1.; 145)
[2025-07-28T12:16:56.924+0000] {local_task_job_runner.py:234} INFO - Task exited with return code 1
[2025-07-28T12:16:56.936+0000] {taskinstance.py:3280} INFO - 0 downstream tasks scheduled from follow-on schedule check
