[2025-07-28T12:14:50.127+0000] {taskinstance.py:1956} INFO - Dependencies all met for dep_context=non-requeueable deps ti=<TaskInstance: dbt_pipeline.dbt_debug scheduled__2025-07-27T00:00:00+00:00 [queued]>
[2025-07-28T12:14:50.132+0000] {taskinstance.py:1956} INFO - Dependencies all met for dep_context=requeueable deps ti=<TaskInstance: dbt_pipeline.dbt_debug scheduled__2025-07-27T00:00:00+00:00 [queued]>
[2025-07-28T12:14:50.132+0000] {taskinstance.py:2170} INFO - Starting attempt 5 of 6
[2025-07-28T12:14:50.136+0000] {taskinstance.py:2191} INFO - Executing <Task(BashOperator): dbt_debug> on 2025-07-27 00:00:00+00:00
[2025-07-28T12:14:50.138+0000] {standard_task_runner.py:60} INFO - Started process 90 to run task
[2025-07-28T12:14:50.140+0000] {standard_task_runner.py:87} INFO - Running: ['***', 'tasks', 'run', 'dbt_pipeline', 'dbt_debug', 'scheduled__2025-07-27T00:00:00+00:00', '--job-id', '9', '--raw', '--subdir', 'DAGS_FOLDER/dbt_pipeline.py', '--cfg-path', '/tmp/tmp1h4psgzf']
[2025-07-28T12:14:50.141+0000] {standard_task_runner.py:88} INFO - Job 9: Subtask dbt_debug
[2025-07-28T12:14:50.148+0000] {warnings.py:109} WARNING - /home/***/.local/lib/python3.8/site-packages/***/settings.py:194: DeprecationWarning: The sql_alchemy_conn option in [core] has been moved to the sql_alchemy_conn option in [database] - the old setting has been used, but please update your config.
  SQL_ALCHEMY_CONN = conf.get("database", "SQL_ALCHEMY_CONN")

[2025-07-28T12:14:50.169+0000] {task_command.py:423} INFO - Running <TaskInstance: dbt_pipeline.dbt_debug scheduled__2025-07-27T00:00:00+00:00 [running]> on host 2c466f0cc933
[2025-07-28T12:14:50.198+0000] {taskinstance.py:2480} INFO - Exporting env vars: AIRFLOW_CTX_DAG_OWNER='gotphoto' AIRFLOW_CTX_DAG_ID='dbt_pipeline' AIRFLOW_CTX_TASK_ID='dbt_debug' AIRFLOW_CTX_EXECUTION_DATE='2025-07-27T00:00:00+00:00' AIRFLOW_CTX_TRY_NUMBER='5' AIRFLOW_CTX_DAG_RUN_ID='scheduled__2025-07-27T00:00:00+00:00'
[2025-07-28T12:14:50.201+0000] {subprocess.py:63} INFO - Tmp dir root location: /tmp
[2025-07-28T12:14:50.201+0000] {subprocess.py:75} INFO - Running command: ['/usr/bin/bash', '-c', 'cd /opt/***/dbt_project && dbt debug --project-dir . --profiles-dir profiles']
[2025-07-28T12:14:50.206+0000] {subprocess.py:86} INFO - Output:
[2025-07-28T12:14:50.209+0000] {subprocess.py:93} INFO - /usr/bin/bash: line 1: dbt: command not found
[2025-07-28T12:14:50.209+0000] {subprocess.py:97} INFO - Command exited with return code 127
[2025-07-28T12:14:50.214+0000] {taskinstance.py:2698} ERROR - Task failed with exception
Traceback (most recent call last):
  File "/home/airflow/.local/lib/python3.8/site-packages/airflow/models/taskinstance.py", line 433, in _execute_task
    result = execute_callable(context=context, **execute_callable_kwargs)
  File "/home/airflow/.local/lib/python3.8/site-packages/airflow/operators/bash.py", line 212, in execute
    raise AirflowException(
airflow.exceptions.AirflowException: Bash command failed. The command returned a non-zero exit code 127.
[2025-07-28T12:14:50.216+0000] {taskinstance.py:1138} INFO - Marking task as UP_FOR_RETRY. dag_id=dbt_pipeline, task_id=dbt_debug, execution_date=20250727T000000, start_date=20250728T121450, end_date=20250728T121450
[2025-07-28T12:14:50.220+0000] {standard_task_runner.py:107} ERROR - Failed to execute job 9 for task dbt_debug (Bash command failed. The command returned a non-zero exit code 127.; 90)
[2025-07-28T12:14:50.242+0000] {local_task_job_runner.py:234} INFO - Task exited with return code 1
[2025-07-28T12:14:50.255+0000] {taskinstance.py:3280} INFO - 0 downstream tasks scheduled from follow-on schedule check
