[2025-07-28T12:24:15.793+0000] {taskinstance.py:1956} INFO - Dependencies all met for dep_context=non-requeueable deps ti=<TaskInstance: dbt_pipeline.dbt_debug scheduled__2025-07-27T00:00:00+00:00 [queued]>
[2025-07-28T12:24:15.796+0000] {taskinstance.py:1956} INFO - Dependencies all met for dep_context=requeueable deps ti=<TaskInstance: dbt_pipeline.dbt_debug scheduled__2025-07-27T00:00:00+00:00 [queued]>
[2025-07-28T12:24:15.796+0000] {taskinstance.py:2170} INFO - Starting attempt 9 of 10
[2025-07-28T12:24:15.800+0000] {taskinstance.py:2191} INFO - Executing <Task(BashOperator): dbt_debug> on 2025-07-27 00:00:00+00:00
[2025-07-28T12:24:15.802+0000] {standard_task_runner.py:60} INFO - Started process 173 to run task
[2025-07-28T12:24:15.804+0000] {standard_task_runner.py:87} INFO - Running: ['***', 'tasks', 'run', 'dbt_pipeline', 'dbt_debug', 'scheduled__2025-07-27T00:00:00+00:00', '--job-id', '17', '--raw', '--subdir', 'DAGS_FOLDER/dbt_pipeline.py', '--cfg-path', '/tmp/tmpgu7_nvwx']
[2025-07-28T12:24:15.806+0000] {standard_task_runner.py:88} INFO - Job 17: Subtask dbt_debug
[2025-07-28T12:24:15.812+0000] {warnings.py:109} WARNING - /home/***/.local/lib/python3.8/site-packages/***/settings.py:194: DeprecationWarning: The sql_alchemy_conn option in [core] has been moved to the sql_alchemy_conn option in [database] - the old setting has been used, but please update your config.
  SQL_ALCHEMY_CONN = conf.get("database", "SQL_ALCHEMY_CONN")

[2025-07-28T12:24:15.834+0000] {task_command.py:423} INFO - Running <TaskInstance: dbt_pipeline.dbt_debug scheduled__2025-07-27T00:00:00+00:00 [running]> on host 689b5ea420e2
[2025-07-28T12:24:15.858+0000] {taskinstance.py:2480} INFO - Exporting env vars: AIRFLOW_CTX_DAG_OWNER='gotphoto' AIRFLOW_CTX_DAG_ID='dbt_pipeline' AIRFLOW_CTX_TASK_ID='dbt_debug' AIRFLOW_CTX_EXECUTION_DATE='2025-07-27T00:00:00+00:00' AIRFLOW_CTX_TRY_NUMBER='9' AIRFLOW_CTX_DAG_RUN_ID='scheduled__2025-07-27T00:00:00+00:00'
[2025-07-28T12:24:15.858+0000] {subprocess.py:63} INFO - Tmp dir root location: /tmp
[2025-07-28T12:24:15.859+0000] {subprocess.py:75} INFO - Running command: ['/usr/bin/bash', '-c', 'cd /opt/***/dbt_project && dbt debug --project-dir . --profiles-dir profiles']
[2025-07-28T12:24:15.862+0000] {subprocess.py:86} INFO - Output:
[2025-07-28T12:24:16.635+0000] {subprocess.py:93} INFO - [0m12:24:16  Running with dbt=1.8.7
[2025-07-28T12:24:16.638+0000] {subprocess.py:93} INFO - [0m12:24:16  dbt version: 1.8.7
[2025-07-28T12:24:16.638+0000] {subprocess.py:93} INFO - [0m12:24:16  python version: 3.8.18
[2025-07-28T12:24:16.639+0000] {subprocess.py:93} INFO - [0m12:24:16  python path: /usr/local/bin/python
[2025-07-28T12:24:16.639+0000] {subprocess.py:93} INFO - [0m12:24:16  os info: Linux-6.12.5-linuxkit-aarch64-with-glibc2.34
[2025-07-28T12:24:17.604+0000] {subprocess.py:93} INFO - [0m12:24:17  Using profiles dir at profiles
[2025-07-28T12:24:17.605+0000] {subprocess.py:93} INFO - [0m12:24:17  Using profiles.yml file at profiles/profiles.yml
[2025-07-28T12:24:17.605+0000] {subprocess.py:93} INFO - [0m12:24:17  Using dbt_project.yml file at ./dbt_project.yml
[2025-07-28T12:24:17.605+0000] {subprocess.py:93} INFO - [0m12:24:17  adapter type: snowflake
[2025-07-28T12:24:17.606+0000] {subprocess.py:93} INFO - [0m12:24:17  adapter version: 1.8.4
[2025-07-28T12:24:17.653+0000] {subprocess.py:93} INFO - [0m12:24:17  Configuration:
[2025-07-28T12:24:17.653+0000] {subprocess.py:93} INFO - [0m12:24:17    profiles.yml file [[32mOK found and valid[0m]
[2025-07-28T12:24:17.654+0000] {subprocess.py:93} INFO - [0m12:24:17    dbt_project.yml file [[32mOK found and valid[0m]
[2025-07-28T12:24:17.654+0000] {subprocess.py:93} INFO - [0m12:24:17  Required dependencies:
[2025-07-28T12:24:17.661+0000] {subprocess.py:93} INFO - [0m12:24:17   - git [[31mERROR[0m]
[2025-07-28T12:24:17.661+0000] {subprocess.py:93} INFO - 
[2025-07-28T12:24:17.661+0000] {subprocess.py:93} INFO - [0m12:24:17  Connection:
[2025-07-28T12:24:17.661+0000] {subprocess.py:93} INFO - [0m12:24:17    account: ANBZLMX-TB05856
[2025-07-28T12:24:17.662+0000] {subprocess.py:93} INFO - [0m12:24:17    user: gotphoto_etl_user
[2025-07-28T12:24:17.662+0000] {subprocess.py:93} INFO - [0m12:24:17    database: GOTPHOTO_ANALYTICS_DB
[2025-07-28T12:24:17.662+0000] {subprocess.py:93} INFO - [0m12:24:17    warehouse: GOTPHOTO_WH
[2025-07-28T12:24:17.662+0000] {subprocess.py:93} INFO - [0m12:24:17    role: gotphoto_etl_role
[2025-07-28T12:24:17.663+0000] {subprocess.py:93} INFO - [0m12:24:17    schema: STAGING
[2025-07-28T12:24:17.663+0000] {subprocess.py:93} INFO - [0m12:24:17    authenticator: None
[2025-07-28T12:24:17.663+0000] {subprocess.py:93} INFO - [0m12:24:17    oauth_client_id: None
[2025-07-28T12:24:17.663+0000] {subprocess.py:93} INFO - [0m12:24:17    query_tag: None
[2025-07-28T12:24:17.663+0000] {subprocess.py:93} INFO - [0m12:24:17    client_session_keep_alive: True
[2025-07-28T12:24:17.664+0000] {subprocess.py:93} INFO - [0m12:24:17    host: None
[2025-07-28T12:24:17.664+0000] {subprocess.py:93} INFO - [0m12:24:17    port: None
[2025-07-28T12:24:17.664+0000] {subprocess.py:93} INFO - [0m12:24:17    proxy_host: None
[2025-07-28T12:24:17.665+0000] {subprocess.py:93} INFO - [0m12:24:17    proxy_port: None
[2025-07-28T12:24:17.665+0000] {subprocess.py:93} INFO - [0m12:24:17    protocol: None
[2025-07-28T12:24:17.665+0000] {subprocess.py:93} INFO - [0m12:24:17    connect_retries: 1
[2025-07-28T12:24:17.665+0000] {subprocess.py:93} INFO - [0m12:24:17    connect_timeout: None
[2025-07-28T12:24:17.666+0000] {subprocess.py:93} INFO - [0m12:24:17    retry_on_database_errors: False
[2025-07-28T12:24:17.666+0000] {subprocess.py:93} INFO - [0m12:24:17    retry_all: False
[2025-07-28T12:24:17.666+0000] {subprocess.py:93} INFO - [0m12:24:17    insecure_mode: False
[2025-07-28T12:24:17.667+0000] {subprocess.py:93} INFO - [0m12:24:17    reuse_connections: None
[2025-07-28T12:24:17.667+0000] {subprocess.py:93} INFO - [0m12:24:17  Registered adapter: snowflake=1.8.4
[2025-07-28T12:24:18.447+0000] {subprocess.py:93} INFO - [0m12:24:18    Connection test: [[31mERROR[0m]
[2025-07-28T12:24:18.447+0000] {subprocess.py:93} INFO - 
[2025-07-28T12:24:18.447+0000] {subprocess.py:93} INFO - [0m12:24:18  [31m2 checks failed:[0m
[2025-07-28T12:24:18.448+0000] {subprocess.py:93} INFO - [0m12:24:18  Error from git --help: Could not find command, ensure it is in the user's PATH: "git"
[2025-07-28T12:24:18.448+0000] {subprocess.py:93} INFO - 
[2025-07-28T12:24:18.448+0000] {subprocess.py:93} INFO - [0m12:24:18  dbt was unable to connect to the specified database.
[2025-07-28T12:24:18.448+0000] {subprocess.py:93} INFO - The database returned the following error:
[2025-07-28T12:24:18.448+0000] {subprocess.py:93} INFO - 
[2025-07-28T12:24:18.448+0000] {subprocess.py:93} INFO -   >Database Error
[2025-07-28T12:24:18.449+0000] {subprocess.py:93} INFO -   250001 (08001): Failed to connect to DB: ANBZLMX-TB05856.snowflakecomputing.com:443. Your user account has been temporarily locked. Try again later or contact your account administrator for assistance. For more information about this error, go to https://community.snowflake.com/s/error-your-user-login-has-been-locked.
[2025-07-28T12:24:18.449+0000] {subprocess.py:93} INFO - 
[2025-07-28T12:24:18.449+0000] {subprocess.py:93} INFO - Check your database credentials and try again. For more information, visit:
[2025-07-28T12:24:18.449+0000] {subprocess.py:93} INFO - https://docs.getdbt.com/docs/configure-your-profile
[2025-07-28T12:24:18.449+0000] {subprocess.py:93} INFO - 
[2025-07-28T12:24:18.449+0000] {subprocess.py:93} INFO - 
[2025-07-28T12:24:19.158+0000] {subprocess.py:97} INFO - Command exited with return code 1
[2025-07-28T12:24:19.163+0000] {taskinstance.py:2698} ERROR - Task failed with exception
Traceback (most recent call last):
  File "/home/airflow/.local/lib/python3.8/site-packages/airflow/models/taskinstance.py", line 433, in _execute_task
    result = execute_callable(context=context, **execute_callable_kwargs)
  File "/home/airflow/.local/lib/python3.8/site-packages/airflow/operators/bash.py", line 212, in execute
    raise AirflowException(
airflow.exceptions.AirflowException: Bash command failed. The command returned a non-zero exit code 1.
[2025-07-28T12:24:19.165+0000] {taskinstance.py:1138} INFO - Marking task as UP_FOR_RETRY. dag_id=dbt_pipeline, task_id=dbt_debug, execution_date=20250727T000000, start_date=20250728T122415, end_date=20250728T122419
[2025-07-28T12:24:19.170+0000] {standard_task_runner.py:107} ERROR - Failed to execute job 17 for task dbt_debug (Bash command failed. The command returned a non-zero exit code 1.; 173)
[2025-07-28T12:24:19.194+0000] {local_task_job_runner.py:234} INFO - Task exited with return code 1
[2025-07-28T12:24:19.207+0000] {taskinstance.py:3280} INFO - 0 downstream tasks scheduled from follow-on schedule check
