[2025-07-28T12:05:39.147+0000] {taskinstance.py:1956} INFO - Dependencies all met for dep_context=non-requeueable deps ti=<TaskInstance: dbt_pipeline.dbt_debug scheduled__2025-07-27T00:00:00+00:00 [queued]>
[2025-07-28T12:05:39.150+0000] {taskinstance.py:1956} INFO - Dependencies all met for dep_context=requeueable deps ti=<TaskInstance: dbt_pipeline.dbt_debug scheduled__2025-07-27T00:00:00+00:00 [queued]>
[2025-07-28T12:05:39.150+0000] {taskinstance.py:2170} INFO - Starting attempt 3 of 4
[2025-07-28T12:05:39.154+0000] {taskinstance.py:2191} INFO - Executing <Task(BashOperator): dbt_debug> on 2025-07-27 00:00:00+00:00
[2025-07-28T12:05:39.156+0000] {standard_task_runner.py:60} INFO - Started process 157 to run task
[2025-07-28T12:05:39.157+0000] {standard_task_runner.py:87} INFO - Running: ['***', 'tasks', 'run', 'dbt_pipeline', 'dbt_debug', 'scheduled__2025-07-27T00:00:00+00:00', '--job-id', '6', '--raw', '--subdir', 'DAGS_FOLDER/dbt_pipeline.py', '--cfg-path', '/tmp/tmp6iburket']
[2025-07-28T12:05:39.158+0000] {standard_task_runner.py:88} INFO - Job 6: Subtask dbt_debug
[2025-07-28T12:05:39.163+0000] {warnings.py:109} WARNING - /home/***/.local/lib/python3.8/site-packages/***/settings.py:194: DeprecationWarning: The sql_alchemy_conn option in [core] has been moved to the sql_alchemy_conn option in [database] - the old setting has been used, but please update your config.
  SQL_ALCHEMY_CONN = conf.get("database", "SQL_ALCHEMY_CONN")

[2025-07-28T12:05:39.182+0000] {task_command.py:423} INFO - Running <TaskInstance: dbt_pipeline.dbt_debug scheduled__2025-07-27T00:00:00+00:00 [running]> on host 0e273d2b8984
[2025-07-28T12:05:39.211+0000] {taskinstance.py:2480} INFO - Exporting env vars: AIRFLOW_CTX_DAG_OWNER='gotphoto' AIRFLOW_CTX_DAG_ID='dbt_pipeline' AIRFLOW_CTX_TASK_ID='dbt_debug' AIRFLOW_CTX_EXECUTION_DATE='2025-07-27T00:00:00+00:00' AIRFLOW_CTX_TRY_NUMBER='3' AIRFLOW_CTX_DAG_RUN_ID='scheduled__2025-07-27T00:00:00+00:00'
[2025-07-28T12:05:39.212+0000] {subprocess.py:63} INFO - Tmp dir root location: /tmp
[2025-07-28T12:05:39.213+0000] {subprocess.py:75} INFO - Running command: ['/usr/bin/bash', '-c', 'cd /opt/***/dbt_project && dbt debug --project-dir . --profiles-dir profiles']
[2025-07-28T12:05:39.218+0000] {subprocess.py:86} INFO - Output:
[2025-07-28T12:05:39.928+0000] {subprocess.py:93} INFO - [0m12:05:39  Running with dbt=1.8.7
[2025-07-28T12:05:39.936+0000] {subprocess.py:93} INFO - [0m12:05:39  dbt version: 1.8.7
[2025-07-28T12:05:39.936+0000] {subprocess.py:93} INFO - [0m12:05:39  python version: 3.8.18
[2025-07-28T12:05:39.936+0000] {subprocess.py:93} INFO - [0m12:05:39  python path: /usr/local/bin/python
[2025-07-28T12:05:39.936+0000] {subprocess.py:93} INFO - [0m12:05:39  os info: Linux-6.12.5-linuxkit-aarch64-with-glibc2.34
[2025-07-28T12:05:40.488+0000] {subprocess.py:93} INFO - [0m12:05:40  Using profiles dir at profiles
[2025-07-28T12:05:40.488+0000] {subprocess.py:93} INFO - [0m12:05:40  Using profiles.yml file at profiles/profiles.yml
[2025-07-28T12:05:40.488+0000] {subprocess.py:93} INFO - [0m12:05:40  Using dbt_project.yml file at ./dbt_project.yml
[2025-07-28T12:05:40.489+0000] {subprocess.py:93} INFO - [0m12:05:40  adapter type: snowflake
[2025-07-28T12:05:40.489+0000] {subprocess.py:93} INFO - [0m12:05:40  adapter version: 1.8.4
[2025-07-28T12:05:40.534+0000] {subprocess.py:93} INFO - [0m12:05:40  Configuration:
[2025-07-28T12:05:40.535+0000] {subprocess.py:93} INFO - [0m12:05:40    profiles.yml file [[32mOK found and valid[0m]
[2025-07-28T12:05:40.535+0000] {subprocess.py:93} INFO - [0m12:05:40    dbt_project.yml file [[32mOK found and valid[0m]
[2025-07-28T12:05:40.535+0000] {subprocess.py:93} INFO - [0m12:05:40  Required dependencies:
[2025-07-28T12:05:40.542+0000] {subprocess.py:93} INFO - [0m12:05:40   - git [[31mERROR[0m]
[2025-07-28T12:05:40.542+0000] {subprocess.py:93} INFO - 
[2025-07-28T12:05:40.542+0000] {subprocess.py:93} INFO - [0m12:05:40  Connection:
[2025-07-28T12:05:40.542+0000] {subprocess.py:93} INFO - [0m12:05:40    account: ANBZLMX-TB05856
[2025-07-28T12:05:40.543+0000] {subprocess.py:93} INFO - [0m12:05:40    user: gotphoto_etl_user
[2025-07-28T12:05:40.543+0000] {subprocess.py:93} INFO - [0m12:05:40    database: GOTPHOTO_ANALYTICS_DB
[2025-07-28T12:05:40.543+0000] {subprocess.py:93} INFO - [0m12:05:40    warehouse: GOTPHOTO_WH
[2025-07-28T12:05:40.543+0000] {subprocess.py:93} INFO - [0m12:05:40    role: gotphoto_etl_role
[2025-07-28T12:05:40.543+0000] {subprocess.py:93} INFO - [0m12:05:40    schema: STAGING
[2025-07-28T12:05:40.544+0000] {subprocess.py:93} INFO - [0m12:05:40    authenticator: None
[2025-07-28T12:05:40.544+0000] {subprocess.py:93} INFO - [0m12:05:40    oauth_client_id: None
[2025-07-28T12:05:40.544+0000] {subprocess.py:93} INFO - [0m12:05:40    query_tag: None
[2025-07-28T12:05:40.544+0000] {subprocess.py:93} INFO - [0m12:05:40    client_session_keep_alive: True
[2025-07-28T12:05:40.545+0000] {subprocess.py:93} INFO - [0m12:05:40    host: None
[2025-07-28T12:05:40.545+0000] {subprocess.py:93} INFO - [0m12:05:40    port: None
[2025-07-28T12:05:40.545+0000] {subprocess.py:93} INFO - [0m12:05:40    proxy_host: None
[2025-07-28T12:05:40.545+0000] {subprocess.py:93} INFO - [0m12:05:40    proxy_port: None
[2025-07-28T12:05:40.545+0000] {subprocess.py:93} INFO - [0m12:05:40    protocol: None
[2025-07-28T12:05:40.546+0000] {subprocess.py:93} INFO - [0m12:05:40    connect_retries: 1
[2025-07-28T12:05:40.546+0000] {subprocess.py:93} INFO - [0m12:05:40    connect_timeout: None
[2025-07-28T12:05:40.546+0000] {subprocess.py:93} INFO - [0m12:05:40    retry_on_database_errors: False
[2025-07-28T12:05:40.546+0000] {subprocess.py:93} INFO - [0m12:05:40    retry_all: False
[2025-07-28T12:05:40.547+0000] {subprocess.py:93} INFO - [0m12:05:40    insecure_mode: False
[2025-07-28T12:05:40.547+0000] {subprocess.py:93} INFO - [0m12:05:40    reuse_connections: None
[2025-07-28T12:05:40.547+0000] {subprocess.py:93} INFO - [0m12:05:40  Registered adapter: snowflake=1.8.4
[2025-07-28T12:05:40.884+0000] {subprocess.py:93} INFO - [0m12:05:40    Connection test: [[31mERROR[0m]
[2025-07-28T12:05:40.885+0000] {subprocess.py:93} INFO - 
[2025-07-28T12:05:40.885+0000] {subprocess.py:93} INFO - [0m12:05:40  [31m2 checks failed:[0m
[2025-07-28T12:05:40.885+0000] {subprocess.py:93} INFO - [0m12:05:40  Error from git --help: User does not have permissions for this command: "git"
[2025-07-28T12:05:40.885+0000] {subprocess.py:93} INFO - 
[2025-07-28T12:05:40.885+0000] {subprocess.py:93} INFO - [0m12:05:40  dbt was unable to connect to the specified database.
[2025-07-28T12:05:40.886+0000] {subprocess.py:93} INFO - The database returned the following error:
[2025-07-28T12:05:40.886+0000] {subprocess.py:93} INFO - 
[2025-07-28T12:05:40.886+0000] {subprocess.py:93} INFO -   >Database Error
[2025-07-28T12:05:40.886+0000] {subprocess.py:93} INFO -   250001 (08001): Failed to connect to DB: ANBZLMX-TB05856.snowflakecomputing.com:443. Incorrect username or password was specified.
[2025-07-28T12:05:40.886+0000] {subprocess.py:93} INFO - 
[2025-07-28T12:05:40.886+0000] {subprocess.py:93} INFO - Check your database credentials and try again. For more information, visit:
[2025-07-28T12:05:40.886+0000] {subprocess.py:93} INFO - https://docs.getdbt.com/docs/configure-your-profile
[2025-07-28T12:05:40.886+0000] {subprocess.py:93} INFO - 
[2025-07-28T12:05:40.887+0000] {subprocess.py:93} INFO - 
[2025-07-28T12:05:41.619+0000] {subprocess.py:97} INFO - Command exited with return code 1
[2025-07-28T12:05:41.624+0000] {taskinstance.py:2698} ERROR - Task failed with exception
Traceback (most recent call last):
  File "/home/airflow/.local/lib/python3.8/site-packages/airflow/models/taskinstance.py", line 433, in _execute_task
    result = execute_callable(context=context, **execute_callable_kwargs)
  File "/home/airflow/.local/lib/python3.8/site-packages/airflow/operators/bash.py", line 212, in execute
    raise AirflowException(
airflow.exceptions.AirflowException: Bash command failed. The command returned a non-zero exit code 1.
[2025-07-28T12:05:41.626+0000] {taskinstance.py:1138} INFO - Marking task as UP_FOR_RETRY. dag_id=dbt_pipeline, task_id=dbt_debug, execution_date=20250727T000000, start_date=20250728T120539, end_date=20250728T120541
[2025-07-28T12:05:41.632+0000] {standard_task_runner.py:107} ERROR - Failed to execute job 6 for task dbt_debug (Bash command failed. The command returned a non-zero exit code 1.; 157)
[2025-07-28T12:05:41.639+0000] {local_task_job_runner.py:234} INFO - Task exited with return code 1
[2025-07-28T12:05:41.650+0000] {taskinstance.py:3280} INFO - 0 downstream tasks scheduled from follow-on schedule check
