[2025-07-28T12:37:30.169+0000] {taskinstance.py:1956} INFO - Dependencies all met for dep_context=non-requeueable deps ti=<TaskInstance: dbt_pipeline.dbt_debug scheduled__2025-07-27T00:00:00+00:00 [queued]>
[2025-07-28T12:37:30.172+0000] {taskinstance.py:1956} INFO - Dependencies all met for dep_context=requeueable deps ti=<TaskInstance: dbt_pipeline.dbt_debug scheduled__2025-07-27T00:00:00+00:00 [queued]>
[2025-07-28T12:37:30.172+0000] {taskinstance.py:2170} INFO - Starting attempt 14 of 15
[2025-07-28T12:37:30.176+0000] {taskinstance.py:2191} INFO - Executing <Task(BashOperator): dbt_debug> on 2025-07-27 00:00:00+00:00
[2025-07-28T12:37:30.178+0000] {standard_task_runner.py:60} INFO - Started process 110 to run task
[2025-07-28T12:37:30.180+0000] {standard_task_runner.py:87} INFO - Running: ['***', 'tasks', 'run', 'dbt_pipeline', 'dbt_debug', 'scheduled__2025-07-27T00:00:00+00:00', '--job-id', '25', '--raw', '--subdir', 'DAGS_FOLDER/dbt_pipeline.py', '--cfg-path', '/tmp/tmpzkwik_lg']
[2025-07-28T12:37:30.181+0000] {standard_task_runner.py:88} INFO - Job 25: Subtask dbt_debug
[2025-07-28T12:37:30.186+0000] {warnings.py:109} WARNING - /home/***/.local/lib/python3.8/site-packages/***/settings.py:194: DeprecationWarning: The sql_alchemy_conn option in [core] has been moved to the sql_alchemy_conn option in [database] - the old setting has been used, but please update your config.
  SQL_ALCHEMY_CONN = conf.get("database", "SQL_ALCHEMY_CONN")

[2025-07-28T12:37:30.210+0000] {task_command.py:423} INFO - Running <TaskInstance: dbt_pipeline.dbt_debug scheduled__2025-07-27T00:00:00+00:00 [running]> on host cc9b7300890b
[2025-07-28T12:37:30.241+0000] {taskinstance.py:2480} INFO - Exporting env vars: AIRFLOW_CTX_DAG_OWNER='gotphoto' AIRFLOW_CTX_DAG_ID='dbt_pipeline' AIRFLOW_CTX_TASK_ID='dbt_debug' AIRFLOW_CTX_EXECUTION_DATE='2025-07-27T00:00:00+00:00' AIRFLOW_CTX_TRY_NUMBER='14' AIRFLOW_CTX_DAG_RUN_ID='scheduled__2025-07-27T00:00:00+00:00'
[2025-07-28T12:37:30.243+0000] {subprocess.py:63} INFO - Tmp dir root location: /tmp
[2025-07-28T12:37:30.245+0000] {subprocess.py:75} INFO - Running command: ['/usr/bin/bash', '-c', 'cd /opt/***/dbt_project && dbt debug --project-dir . --profiles-dir profiles']
[2025-07-28T12:37:30.249+0000] {subprocess.py:86} INFO - Output:
[2025-07-28T12:37:31.059+0000] {subprocess.py:93} INFO - [0m12:37:31  Running with dbt=1.9.0-b2
[2025-07-28T12:37:31.066+0000] {subprocess.py:93} INFO - [0m12:37:31  dbt version: 1.9.0-b2
[2025-07-28T12:37:31.066+0000] {subprocess.py:93} INFO - [0m12:37:31  python version: 3.8.18
[2025-07-28T12:37:31.066+0000] {subprocess.py:93} INFO - [0m12:37:31  python path: /usr/local/bin/python
[2025-07-28T12:37:31.067+0000] {subprocess.py:93} INFO - [0m12:37:31  os info: Linux-6.12.5-linuxkit-aarch64-with-glibc2.34
[2025-07-28T12:37:31.070+0000] {subprocess.py:93} INFO - [0m12:37:31  Error importing adapter: No module named 'dbt.adapters.snowflake'
[2025-07-28T12:37:31.071+0000] {subprocess.py:93} INFO - [0m12:37:31  Using profiles dir at profiles
[2025-07-28T12:37:31.071+0000] {subprocess.py:93} INFO - [0m12:37:31  Using profiles.yml file at profiles/profiles.yml
[2025-07-28T12:37:31.071+0000] {subprocess.py:93} INFO - [0m12:37:31  Using dbt_project.yml file at ./dbt_project.yml
[2025-07-28T12:37:31.119+0000] {subprocess.py:93} INFO - [0m12:37:31  Configuration:
[2025-07-28T12:37:31.120+0000] {subprocess.py:93} INFO - [0m12:37:31    profiles.yml file [[31mERROR invalid[0m]
[2025-07-28T12:37:31.120+0000] {subprocess.py:93} INFO - [0m12:37:31    dbt_project.yml file [[32mOK found and valid[0m]
[2025-07-28T12:37:31.120+0000] {subprocess.py:93} INFO - [0m12:37:31  Required dependencies:
[2025-07-28T12:37:31.126+0000] {subprocess.py:93} INFO - [0m12:37:31   - git [[32mOK found[0m]
[2025-07-28T12:37:31.126+0000] {subprocess.py:93} INFO - 
[2025-07-28T12:37:31.126+0000] {subprocess.py:93} INFO - [0m12:37:31  Connection test skipped since no profile was found
[2025-07-28T12:37:31.126+0000] {subprocess.py:93} INFO - [0m12:37:31  [31m1 check failed:[0m
[2025-07-28T12:37:31.126+0000] {subprocess.py:93} INFO - [0m12:37:31  Profile loading failed for the following reason:
[2025-07-28T12:37:31.127+0000] {subprocess.py:93} INFO - Runtime Error
[2025-07-28T12:37:31.127+0000] {subprocess.py:93} INFO -   Credentials in profile "gotphoto_dbt_project", target "dev" invalid: Runtime Error
[2025-07-28T12:37:31.127+0000] {subprocess.py:93} INFO -     Could not find adapter type snowflake!
[2025-07-28T12:37:31.127+0000] {subprocess.py:93} INFO - 
[2025-07-28T12:37:31.127+0000] {subprocess.py:93} INFO - 
[2025-07-28T12:37:31.752+0000] {subprocess.py:97} INFO - Command exited with return code 1
[2025-07-28T12:37:31.758+0000] {taskinstance.py:2698} ERROR - Task failed with exception
Traceback (most recent call last):
  File "/home/airflow/.local/lib/python3.8/site-packages/airflow/models/taskinstance.py", line 433, in _execute_task
    result = execute_callable(context=context, **execute_callable_kwargs)
  File "/home/airflow/.local/lib/python3.8/site-packages/airflow/operators/bash.py", line 212, in execute
    raise AirflowException(
airflow.exceptions.AirflowException: Bash command failed. The command returned a non-zero exit code 1.
[2025-07-28T12:37:31.760+0000] {taskinstance.py:1138} INFO - Marking task as UP_FOR_RETRY. dag_id=dbt_pipeline, task_id=dbt_debug, execution_date=20250727T000000, start_date=20250728T123730, end_date=20250728T123731
[2025-07-28T12:37:31.766+0000] {standard_task_runner.py:107} ERROR - Failed to execute job 25 for task dbt_debug (Bash command failed. The command returned a non-zero exit code 1.; 110)
[2025-07-28T12:37:31.798+0000] {local_task_job_runner.py:234} INFO - Task exited with return code 1
[2025-07-28T12:37:31.814+0000] {taskinstance.py:3280} INFO - 0 downstream tasks scheduled from follow-on schedule check
