[2025-07-28T12:27:03.266+0000] {taskinstance.py:1956} INFO - Dependencies all met for dep_context=non-requeueable deps ti=<TaskInstance: dbt_pipeline.dbt_debug scheduled__2025-07-27T00:00:00+00:00 [queued]>
[2025-07-28T12:27:03.269+0000] {taskinstance.py:1956} INFO - Dependencies all met for dep_context=requeueable deps ti=<TaskInstance: dbt_pipeline.dbt_debug scheduled__2025-07-27T00:00:00+00:00 [queued]>
[2025-07-28T12:27:03.269+0000] {taskinstance.py:2170} INFO - Starting attempt 11 of 12
[2025-07-28T12:27:03.273+0000] {taskinstance.py:2191} INFO - Executing <Task(BashOperator): dbt_debug> on 2025-07-27 00:00:00+00:00
[2025-07-28T12:27:03.275+0000] {standard_task_runner.py:60} INFO - Started process 350 to run task
[2025-07-28T12:27:03.276+0000] {standard_task_runner.py:87} INFO - Running: ['***', 'tasks', 'run', 'dbt_pipeline', 'dbt_debug', 'scheduled__2025-07-27T00:00:00+00:00', '--job-id', '19', '--raw', '--subdir', 'DAGS_FOLDER/dbt_pipeline.py', '--cfg-path', '/tmp/tmpn4tmi9ai']
[2025-07-28T12:27:03.278+0000] {standard_task_runner.py:88} INFO - Job 19: Subtask dbt_debug
[2025-07-28T12:27:03.283+0000] {warnings.py:109} WARNING - /home/***/.local/lib/python3.8/site-packages/***/settings.py:194: DeprecationWarning: The sql_alchemy_conn option in [core] has been moved to the sql_alchemy_conn option in [database] - the old setting has been used, but please update your config.
  SQL_ALCHEMY_CONN = conf.get("database", "SQL_ALCHEMY_CONN")

[2025-07-28T12:27:03.302+0000] {task_command.py:423} INFO - Running <TaskInstance: dbt_pipeline.dbt_debug scheduled__2025-07-27T00:00:00+00:00 [running]> on host 689b5ea420e2
[2025-07-28T12:27:03.326+0000] {taskinstance.py:2480} INFO - Exporting env vars: AIRFLOW_CTX_DAG_OWNER='gotphoto' AIRFLOW_CTX_DAG_ID='dbt_pipeline' AIRFLOW_CTX_TASK_ID='dbt_debug' AIRFLOW_CTX_EXECUTION_DATE='2025-07-27T00:00:00+00:00' AIRFLOW_CTX_TRY_NUMBER='11' AIRFLOW_CTX_DAG_RUN_ID='scheduled__2025-07-27T00:00:00+00:00'
[2025-07-28T12:27:03.328+0000] {subprocess.py:63} INFO - Tmp dir root location: /tmp
[2025-07-28T12:27:03.328+0000] {subprocess.py:75} INFO - Running command: ['/usr/bin/bash', '-c', 'cd /opt/***/dbt_project && dbt debug --project-dir . --profiles-dir profiles']
[2025-07-28T12:27:03.333+0000] {subprocess.py:86} INFO - Output:
[2025-07-28T12:27:04.012+0000] {subprocess.py:93} INFO - [0m12:27:04  Running with dbt=1.8.7
[2025-07-28T12:27:04.018+0000] {subprocess.py:93} INFO - [0m12:27:04  dbt version: 1.8.7
[2025-07-28T12:27:04.018+0000] {subprocess.py:93} INFO - [0m12:27:04  python version: 3.8.18
[2025-07-28T12:27:04.019+0000] {subprocess.py:93} INFO - [0m12:27:04  python path: /usr/local/bin/python
[2025-07-28T12:27:04.019+0000] {subprocess.py:93} INFO - [0m12:27:04  os info: Linux-6.12.5-linuxkit-aarch64-with-glibc2.34
[2025-07-28T12:27:04.536+0000] {subprocess.py:93} INFO - [0m12:27:04  Using profiles dir at profiles
[2025-07-28T12:27:04.537+0000] {subprocess.py:93} INFO - [0m12:27:04  Using profiles.yml file at profiles/profiles.yml
[2025-07-28T12:27:04.537+0000] {subprocess.py:93} INFO - [0m12:27:04  Using dbt_project.yml file at ./dbt_project.yml
[2025-07-28T12:27:04.537+0000] {subprocess.py:93} INFO - [0m12:27:04  adapter type: snowflake
[2025-07-28T12:27:04.537+0000] {subprocess.py:93} INFO - [0m12:27:04  adapter version: 1.8.4
[2025-07-28T12:27:04.578+0000] {subprocess.py:93} INFO - [0m12:27:04  Configuration:
[2025-07-28T12:27:04.578+0000] {subprocess.py:93} INFO - [0m12:27:04    profiles.yml file [[32mOK found and valid[0m]
[2025-07-28T12:27:04.579+0000] {subprocess.py:93} INFO - [0m12:27:04    dbt_project.yml file [[32mOK found and valid[0m]
[2025-07-28T12:27:04.579+0000] {subprocess.py:93} INFO - [0m12:27:04  Required dependencies:
[2025-07-28T12:27:04.587+0000] {subprocess.py:93} INFO - [0m12:27:04   - git [[31mERROR[0m]
[2025-07-28T12:27:04.587+0000] {subprocess.py:93} INFO - 
[2025-07-28T12:27:04.587+0000] {subprocess.py:93} INFO - [0m12:27:04  Connection:
[2025-07-28T12:27:04.587+0000] {subprocess.py:93} INFO - [0m12:27:04    account: ANBZLMX-TB05856
[2025-07-28T12:27:04.587+0000] {subprocess.py:93} INFO - [0m12:27:04    user: gotphoto_etl_user
[2025-07-28T12:27:04.587+0000] {subprocess.py:93} INFO - [0m12:27:04    database: GOTPHOTO_ANALYTICS_DB
[2025-07-28T12:27:04.588+0000] {subprocess.py:93} INFO - [0m12:27:04    warehouse: GOTPHOTO_WH
[2025-07-28T12:27:04.588+0000] {subprocess.py:93} INFO - [0m12:27:04    role: gotphoto_etl_role
[2025-07-28T12:27:04.588+0000] {subprocess.py:93} INFO - [0m12:27:04    schema: STAGING
[2025-07-28T12:27:04.588+0000] {subprocess.py:93} INFO - [0m12:27:04    authenticator: None
[2025-07-28T12:27:04.588+0000] {subprocess.py:93} INFO - [0m12:27:04    oauth_client_id: None
[2025-07-28T12:27:04.588+0000] {subprocess.py:93} INFO - [0m12:27:04    query_tag: None
[2025-07-28T12:27:04.589+0000] {subprocess.py:93} INFO - [0m12:27:04    client_session_keep_alive: True
[2025-07-28T12:27:04.589+0000] {subprocess.py:93} INFO - [0m12:27:04    host: None
[2025-07-28T12:27:04.589+0000] {subprocess.py:93} INFO - [0m12:27:04    port: None
[2025-07-28T12:27:04.589+0000] {subprocess.py:93} INFO - [0m12:27:04    proxy_host: None
[2025-07-28T12:27:04.589+0000] {subprocess.py:93} INFO - [0m12:27:04    proxy_port: None
[2025-07-28T12:27:04.589+0000] {subprocess.py:93} INFO - [0m12:27:04    protocol: None
[2025-07-28T12:27:04.590+0000] {subprocess.py:93} INFO - [0m12:27:04    connect_retries: 1
[2025-07-28T12:27:04.590+0000] {subprocess.py:93} INFO - [0m12:27:04    connect_timeout: None
[2025-07-28T12:27:04.590+0000] {subprocess.py:93} INFO - [0m12:27:04    retry_on_database_errors: False
[2025-07-28T12:27:04.590+0000] {subprocess.py:93} INFO - [0m12:27:04    retry_all: False
[2025-07-28T12:27:04.590+0000] {subprocess.py:93} INFO - [0m12:27:04    insecure_mode: False
[2025-07-28T12:27:04.591+0000] {subprocess.py:93} INFO - [0m12:27:04    reuse_connections: None
[2025-07-28T12:27:04.591+0000] {subprocess.py:93} INFO - [0m12:27:04  Registered adapter: snowflake=1.8.4
[2025-07-28T12:27:05.139+0000] {subprocess.py:93} INFO - [0m12:27:05    Connection test: [[32mOK connection ok[0m]
[2025-07-28T12:27:05.140+0000] {subprocess.py:93} INFO - 
[2025-07-28T12:27:05.140+0000] {subprocess.py:93} INFO - [0m12:27:05  [31m1 check failed:[0m
[2025-07-28T12:27:05.140+0000] {subprocess.py:93} INFO - [0m12:27:05  Error from git --help: Could not find command, ensure it is in the user's PATH: "git"
[2025-07-28T12:27:05.141+0000] {subprocess.py:93} INFO - 
[2025-07-28T12:27:05.856+0000] {subprocess.py:97} INFO - Command exited with return code 1
[2025-07-28T12:27:05.862+0000] {taskinstance.py:2698} ERROR - Task failed with exception
Traceback (most recent call last):
  File "/home/airflow/.local/lib/python3.8/site-packages/airflow/models/taskinstance.py", line 433, in _execute_task
    result = execute_callable(context=context, **execute_callable_kwargs)
  File "/home/airflow/.local/lib/python3.8/site-packages/airflow/operators/bash.py", line 212, in execute
    raise AirflowException(
airflow.exceptions.AirflowException: Bash command failed. The command returned a non-zero exit code 1.
[2025-07-28T12:27:05.863+0000] {taskinstance.py:1138} INFO - Marking task as UP_FOR_RETRY. dag_id=dbt_pipeline, task_id=dbt_debug, execution_date=20250727T000000, start_date=20250728T122703, end_date=20250728T122705
[2025-07-28T12:27:05.869+0000] {standard_task_runner.py:107} ERROR - Failed to execute job 19 for task dbt_debug (Bash command failed. The command returned a non-zero exit code 1.; 350)
[2025-07-28T12:27:05.884+0000] {local_task_job_runner.py:234} INFO - Task exited with return code 1
[2025-07-28T12:27:05.897+0000] {taskinstance.py:3280} INFO - 0 downstream tasks scheduled from follow-on schedule check
