[2025-07-28T12:03:25.493+0000] {taskinstance.py:1956} INFO - Dependencies all met for dep_context=non-requeueable deps ti=<TaskInstance: dbt_pipeline.dbt_debug scheduled__2025-07-27T00:00:00+00:00 [queued]>
[2025-07-28T12:03:25.496+0000] {taskinstance.py:1956} INFO - Dependencies all met for dep_context=requeueable deps ti=<TaskInstance: dbt_pipeline.dbt_debug scheduled__2025-07-27T00:00:00+00:00 [queued]>
[2025-07-28T12:03:25.496+0000] {taskinstance.py:2170} INFO - Starting attempt 1 of 2
[2025-07-28T12:03:25.500+0000] {taskinstance.py:2191} INFO - Executing <Task(BashOperator): dbt_debug> on 2025-07-27 00:00:00+00:00
[2025-07-28T12:03:25.502+0000] {standard_task_runner.py:60} INFO - Started process 162 to run task
[2025-07-28T12:03:25.504+0000] {standard_task_runner.py:87} INFO - Running: ['***', 'tasks', 'run', 'dbt_pipeline', 'dbt_debug', 'scheduled__2025-07-27T00:00:00+00:00', '--job-id', '3', '--raw', '--subdir', 'DAGS_FOLDER/dbt_pipeline.py', '--cfg-path', '/tmp/tmpl66vpv55']
[2025-07-28T12:03:25.504+0000] {standard_task_runner.py:88} INFO - Job 3: Subtask dbt_debug
[2025-07-28T12:03:25.509+0000] {warnings.py:109} WARNING - /home/***/.local/lib/python3.8/site-packages/***/settings.py:194: DeprecationWarning: The sql_alchemy_conn option in [core] has been moved to the sql_alchemy_conn option in [database] - the old setting has been used, but please update your config.
  SQL_ALCHEMY_CONN = conf.get("database", "SQL_ALCHEMY_CONN")

[2025-07-28T12:03:25.529+0000] {task_command.py:423} INFO - Running <TaskInstance: dbt_pipeline.dbt_debug scheduled__2025-07-27T00:00:00+00:00 [running]> on host 2ca4a30ef3fb
[2025-07-28T12:03:25.554+0000] {taskinstance.py:2480} INFO - Exporting env vars: AIRFLOW_CTX_DAG_OWNER='gotphoto' AIRFLOW_CTX_DAG_ID='dbt_pipeline' AIRFLOW_CTX_TASK_ID='dbt_debug' AIRFLOW_CTX_EXECUTION_DATE='2025-07-27T00:00:00+00:00' AIRFLOW_CTX_TRY_NUMBER='1' AIRFLOW_CTX_DAG_RUN_ID='scheduled__2025-07-27T00:00:00+00:00'
[2025-07-28T12:03:25.556+0000] {subprocess.py:63} INFO - Tmp dir root location: /tmp
[2025-07-28T12:03:25.556+0000] {subprocess.py:75} INFO - Running command: ['/usr/bin/bash', '-c', 'cd /opt/***/dbt_project && dbt debug --project-dir . --profiles-dir profiles']
[2025-07-28T12:03:25.560+0000] {subprocess.py:86} INFO - Output:
[2025-07-28T12:03:25.567+0000] {subprocess.py:93} INFO - /usr/bin/bash: line 1: dbt: command not found
[2025-07-28T12:03:25.567+0000] {subprocess.py:97} INFO - Command exited with return code 127
[2025-07-28T12:03:25.572+0000] {taskinstance.py:2698} ERROR - Task failed with exception
Traceback (most recent call last):
  File "/home/airflow/.local/lib/python3.8/site-packages/airflow/models/taskinstance.py", line 433, in _execute_task
    result = execute_callable(context=context, **execute_callable_kwargs)
  File "/home/airflow/.local/lib/python3.8/site-packages/airflow/operators/bash.py", line 212, in execute
    raise AirflowException(
airflow.exceptions.AirflowException: Bash command failed. The command returned a non-zero exit code 127.
[2025-07-28T12:03:25.574+0000] {taskinstance.py:1138} INFO - Marking task as UP_FOR_RETRY. dag_id=dbt_pipeline, task_id=dbt_debug, execution_date=20250727T000000, start_date=20250728T120325, end_date=20250728T120325
[2025-07-28T12:03:25.579+0000] {standard_task_runner.py:107} ERROR - Failed to execute job 3 for task dbt_debug (Bash command failed. The command returned a non-zero exit code 127.; 162)
[2025-07-28T12:03:25.605+0000] {local_task_job_runner.py:234} INFO - Task exited with return code 1
[2025-07-28T12:03:25.617+0000] {taskinstance.py:3280} INFO - 0 downstream tasks scheduled from follow-on schedule check
